<?xml version="1.0"?>
<robot xmlns:xacro="http://ros.org/wiki/xacro">
  <xacro:include filename="$(find sample_robot_description)/urdf/wheel/wheel.gazebo.xacro" />
  <xacro:include filename="$(find sample_robot_description)/urdf/wheel/wheel.transmission.xacro" />
  <xacro:macro name="wheel" params="prefix parent *joint_origin *joint_axis">
    <joint name="${prefix}_wheel_joint" type="continuous">
      <xacro:insert_block name="joint_origin" />
      <xacro:insert_block name="joint_axis" />
      <parent link="${parent}" />
      <child link="${prefix}_wheel" />
    </joint>
    
    <link name="${prefix}_wheel">
      <visual>
        <geometry>
          <cylinder radius="0.1" length="0.05"/>
        </geometry>
      </visual>
      
      <collision>
        <geometry>
          <cylinder radius="0.1" length="0.05"/>
        </geometry>
      </collision>
      
      <inertial>
        <origin xyz="0.0 0.0 0.0" />
        <mass value="0.500"/>
        <inertia ixx="0.0013541667" ixy="0" ixz="0" iyy="0.0013541667" iyz="0" izz="0.0025"/>
      </inertial>
    </link>
  </xacro:macro>
</robot>
